Traceback (most recent call last):
  File "C:\Users\olive\Anaconda\lib\site-packages\jupyter_cache\executors\utils.py", line 51, in single_nb_execution
    executenb(
  File "C:\Users\olive\Anaconda\lib\site-packages\nbclient\client.py", line 1112, in execute
    return NotebookClient(nb=nb, resources=resources, km=km, **kwargs).execute()
  File "C:\Users\olive\Anaconda\lib\site-packages\nbclient\util.py", line 74, in wrapped
    return just_run(coro(*args, **kwargs))
  File "C:\Users\olive\Anaconda\lib\site-packages\nbclient\util.py", line 53, in just_run
    return loop.run_until_complete(coro)
  File "C:\Users\olive\Anaconda\lib\asyncio\base_events.py", line 642, in run_until_complete
    return future.result()
  File "C:\Users\olive\Anaconda\lib\site-packages\nbclient\client.py", line 553, in async_execute
    await self.async_execute_cell(
  File "C:\Users\olive\Anaconda\lib\site-packages\nbclient\client.py", line 857, in async_execute_cell
    self._check_raise_for_error(cell, exec_reply)
  File "C:\Users\olive\Anaconda\lib\site-packages\nbclient\client.py", line 760, in _check_raise_for_error
    raise CellExecutionError.from_cell_and_msg(cell, exec_reply_content)
nbclient.exceptions.CellExecutionError: An error occurred while executing the following cell:
------------------
sns.displot(data=df, x="median_house_value", kind="kde" )
------------------

[1;31m---------------------------------------------------------------------------[0m
[1;31mTypeError[0m                                 Traceback (most recent call last)
[1;32m~\AppData\Local\Temp/ipykernel_18856/2021759643.py[0m in [0;36m<module>[1;34m[0m
[1;32m----> 1[1;33m [0msns[0m[1;33m.[0m[0mdisplot[0m[1;33m([0m[0mdata[0m[1;33m=[0m[0mdf[0m[1;33m,[0m [0mx[0m[1;33m=[0m[1;34m"median_house_value"[0m[1;33m,[0m [0mkind[0m[1;33m=[0m[1;34m"kde"[0m [1;33m)[0m[1;33m[0m[1;33m[0m[0m
[0m
[1;32m~\Anaconda\lib\site-packages\seaborn\distributions.py[0m in [0;36mdisplot[1;34m(data, x, y, hue, row, col, weights, kind, rug, rug_kws, log_scale, legend, palette, hue_order, hue_norm, color, col_wrap, row_order, col_order, height, aspect, facet_kws, **kwargs)[0m
[0;32m   2240[0m     [1;32melse[0m[1;33m:[0m[1;33m[0m[1;33m[0m[0m
[0;32m   2241[0m         [0mallowed_types[0m [1;33m=[0m [1;32mNone[0m[1;33m[0m[1;33m[0m[0m
[1;32m-> 2242[1;33m     [0mp[0m[1;33m.[0m[0m_attach[0m[1;33m([0m[0mg[0m[1;33m,[0m [0mallowed_types[0m[1;33m=[0m[0mallowed_types[0m[1;33m,[0m [0mlog_scale[0m[1;33m=[0m[0mlog_scale[0m[1;33m)[0m[1;33m[0m[1;33m[0m[0m
[0m[0;32m   2243[0m [1;33m[0m[0m
[0;32m   2244[0m     [1;31m# Check for a specification that lacks x/y data and return early[0m[1;33m[0m[1;33m[0m[0m

[1;32m~\Anaconda\lib\site-packages\seaborn\_core.py[0m in [0;36m_attach[1;34m(self, obj, allowed_types, log_scale)[0m
[0;32m   1123[0m                     [1;34mf"{allowed_types} is required"[0m[1;33m[0m[1;33m[0m[0m
[0;32m   1124[0m                 )
[1;32m-> 1125[1;33m                 [1;32mraise[0m [0mTypeError[0m[1;33m([0m[0merr[0m[1;33m)[0m[1;33m[0m[1;33m[0m[0m
[0m[0;32m   1126[0m [1;33m[0m[0m
[0;32m   1127[0m             [1;31m# Register with the matplotlib unit conversion machinery[0m[1;33m[0m[1;33m[0m[0m

[1;31mTypeError[0m: The x variable is categorical, but one of ['numeric', 'datetime'] is required
TypeError: The x variable is categorical, but one of ['numeric', 'datetime'] is required

